[2024-04-14T19:29:53.253+0000] {local_task_job_runner.py:120} INFO - ::group::Pre task execution logs
[2024-04-14T19:29:53.272+0000] {taskinstance.py:2073} INFO - Dependencies all met for dep_context=non-requeueable deps ti=<TaskInstance: extract_and_load_equipment.extract_task manual__2024-04-14T19:29:51.418478+00:00 [queued]>
[2024-04-14T19:29:53.278+0000] {taskinstance.py:2073} INFO - Dependencies all met for dep_context=requeueable deps ti=<TaskInstance: extract_and_load_equipment.extract_task manual__2024-04-14T19:29:51.418478+00:00 [queued]>
[2024-04-14T19:29:53.279+0000] {taskinstance.py:2303} INFO - Starting attempt 1 of 1
[2024-04-14T19:29:53.291+0000] {taskinstance.py:2327} INFO - Executing <Task(PythonOperator): extract_task> on 2024-04-14 19:29:51.418478+00:00
[2024-04-14T19:29:53.299+0000] {warnings.py:110} WARNING - /home/***/.local/lib/python3.12/site-packages/***/task/task_runner/standard_task_runner.py:61: DeprecationWarning: This process (pid=556) is multi-threaded, use of fork() may lead to deadlocks in the child.
  pid = os.fork()

[2024-04-14T19:29:53.300+0000] {standard_task_runner.py:63} INFO - Started process 558 to run task
[2024-04-14T19:29:53.300+0000] {standard_task_runner.py:90} INFO - Running: ['***', 'tasks', 'run', 'extract_and_load_equipment', 'extract_task', 'manual__2024-04-14T19:29:51.418478+00:00', '--job-id', '12', '--raw', '--subdir', 'DAGS_FOLDER/dag_equipment.py', '--cfg-path', '/tmp/tmpchai7pe1']
[2024-04-14T19:29:53.301+0000] {standard_task_runner.py:91} INFO - Job 12: Subtask extract_task
[2024-04-14T19:29:53.352+0000] {task_command.py:426} INFO - Running <TaskInstance: extract_and_load_equipment.extract_task manual__2024-04-14T19:29:51.418478+00:00 [running]> on host 96fabfb48c01
[2024-04-14T19:29:53.437+0000] {taskinstance.py:2644} INFO - Exporting env vars: AIRFLOW_CTX_DAG_OWNER='***' AIRFLOW_CTX_DAG_ID='extract_and_load_equipment' AIRFLOW_CTX_TASK_ID='extract_task' AIRFLOW_CTX_EXECUTION_DATE='2024-04-14T19:29:51.418478+00:00' AIRFLOW_CTX_TRY_NUMBER='1' AIRFLOW_CTX_DAG_RUN_ID='manual__2024-04-14T19:29:51.418478+00:00'
[2024-04-14T19:29:53.438+0000] {taskinstance.py:430} INFO - ::endgroup::
[2024-04-14T19:29:53.439+0000] {taskinstance.py:441} INFO - ::group::Post task execution logs
[2024-04-14T19:29:53.440+0000] {taskinstance.py:2890} ERROR - Task failed with exception
Traceback (most recent call last):
  File "/home/airflow/.local/lib/python3.12/site-packages/airflow/models/taskinstance.py", line 465, in _execute_task
    result = _execute_callable(context=context, **execute_callable_kwargs)
             ^^^^^^^^^^^^^^^^^^^^^^^^^^^^^^^^^^^^^^^^^^^^^^^^^^^^^^^^^^^^^
  File "/home/airflow/.local/lib/python3.12/site-packages/airflow/models/taskinstance.py", line 432, in _execute_callable
    return execute_callable(context=context, **execute_callable_kwargs)
           ^^^^^^^^^^^^^^^^^^^^^^^^^^^^^^^^^^^^^^^^^^^^^^^^^^^^^^^^^^^^
  File "/home/airflow/.local/lib/python3.12/site-packages/airflow/models/baseoperator.py", line 400, in wrapper
    return func(self, *args, **kwargs)
           ^^^^^^^^^^^^^^^^^^^^^^^^^^^
  File "/home/airflow/.local/lib/python3.12/site-packages/airflow/operators/python.py", line 235, in execute
    return_value = self.execute_callable()
                   ^^^^^^^^^^^^^^^^^^^^^^^
  File "/home/airflow/.local/lib/python3.12/site-packages/airflow/operators/python.py", line 252, in execute_callable
    return self.python_callable(*self.op_args, **self.op_kwargs)
           ^^^^^^^^^^^^^^^^^^^^^^^^^^^^^^^^^^^^^^^^^^^^^^^^^^^^^
  File "/opt/airflow/dags/dag_equipment.py", line 11, in extract_to_dataframe
    df = Extract(PATH_JSON_EQUIPMENT).to_dataframe()
         ^^^^^^^^^^^^^^^^^^^^^^^^^^^^^^^^^^^^^^^^^^^
  File "/opt/airflow/dags/classes/extract.py", line 10, in to_dataframe
    return self._read_json()
           ^^^^^^^^^^^^^^^^^
  File "/opt/airflow/dags/classes/extract.py", line 17, in _read_json
    with open(self.file_path, 'r') as file:
         ^^^^^^^^^^^^^^^^^^^^^^^^^
FileNotFoundError: [Errno 2] No such file or directory: 'C:/Users/User/Desktop/Challgenge-Tech/equipment.json'
[2024-04-14T19:29:53.451+0000] {taskinstance.py:1205} INFO - Marking task as FAILED. dag_id=extract_and_load_equipment, task_id=extract_task, execution_date=20240414T192951, start_date=20240414T192953, end_date=20240414T192953
[2024-04-14T19:29:53.462+0000] {standard_task_runner.py:110} ERROR - Failed to execute job 12 for task extract_task ([Errno 2] No such file or directory: 'C:/Users/User/Desktop/Challgenge-Tech/equipment.json'; 558)
[2024-04-14T19:29:53.474+0000] {local_task_job_runner.py:240} INFO - Task exited with return code 1
[2024-04-14T19:29:53.491+0000] {taskinstance.py:3482} INFO - 0 downstream tasks scheduled from follow-on schedule check
[2024-04-14T19:29:53.497+0000] {local_task_job_runner.py:222} INFO - ::endgroup::
