[2024-04-15T00:11:57.748+0000] {local_task_job_runner.py:120} INFO - ::group::Pre task execution logs
[2024-04-15T00:11:57.787+0000] {taskinstance.py:2073} INFO - Dependencies all met for dep_context=non-requeueable deps ti=<TaskInstance: extract_and_load_equipment_sensors.load_to_mysql scheduled__2023-06-19T00:00:00+00:00 [queued]>
[2024-04-15T00:11:57.801+0000] {taskinstance.py:2073} INFO - Dependencies all met for dep_context=requeueable deps ti=<TaskInstance: extract_and_load_equipment_sensors.load_to_mysql scheduled__2023-06-19T00:00:00+00:00 [queued]>
[2024-04-15T00:11:57.804+0000] {taskinstance.py:2303} INFO - Starting attempt 1 of 1
[2024-04-15T00:11:57.827+0000] {taskinstance.py:2327} INFO - Executing <Task(PythonOperator): load_to_mysql> on 2023-06-19 00:00:00+00:00
[2024-04-15T00:11:57.845+0000] {warnings.py:110} WARNING - /home/***/.local/lib/python3.12/site-packages/***/task/task_runner/standard_task_runner.py:61: DeprecationWarning: This process (pid=4897) is multi-threaded, use of fork() may lead to deadlocks in the child.
  pid = os.fork()

[2024-04-15T00:11:57.847+0000] {standard_task_runner.py:63} INFO - Started process 4935 to run task
[2024-04-15T00:11:57.847+0000] {standard_task_runner.py:90} INFO - Running: ['***', 'tasks', 'run', 'extract_and_load_equipment_sensors', 'load_to_mysql', 'scheduled__2023-06-19T00:00:00+00:00', '--job-id', '1458', '--raw', '--subdir', 'DAGS_FOLDER/dag_equipment_sensors.py', '--cfg-path', '/tmp/tmptakba_l4']
[2024-04-15T00:11:57.855+0000] {standard_task_runner.py:91} INFO - Job 1458: Subtask load_to_mysql
[2024-04-15T00:11:57.913+0000] {task_command.py:426} INFO - Running <TaskInstance: extract_and_load_equipment_sensors.load_to_mysql scheduled__2023-06-19T00:00:00+00:00 [running]> on host cb5b33b73a08
[2024-04-15T00:11:58.059+0000] {taskinstance.py:2644} INFO - Exporting env vars: AIRFLOW_CTX_DAG_OWNER='***' AIRFLOW_CTX_DAG_ID='extract_and_load_equipment_sensors' AIRFLOW_CTX_TASK_ID='load_to_mysql' AIRFLOW_CTX_EXECUTION_DATE='2023-06-19T00:00:00+00:00' AIRFLOW_CTX_TRY_NUMBER='1' AIRFLOW_CTX_DAG_RUN_ID='scheduled__2023-06-19T00:00:00+00:00'
[2024-04-15T00:11:58.062+0000] {taskinstance.py:430} INFO - ::endgroup::
[2024-04-15T00:11:58.071+0000] {taskinstance.py:441} INFO - ::group::Post task execution logs
[2024-04-15T00:11:58.072+0000] {taskinstance.py:2890} ERROR - Task failed with exception
Traceback (most recent call last):
  File "/home/airflow/.local/lib/python3.12/site-packages/airflow/models/taskinstance.py", line 465, in _execute_task
    result = _execute_callable(context=context, **execute_callable_kwargs)
             ^^^^^^^^^^^^^^^^^^^^^^^^^^^^^^^^^^^^^^^^^^^^^^^^^^^^^^^^^^^^^
  File "/home/airflow/.local/lib/python3.12/site-packages/airflow/models/taskinstance.py", line 432, in _execute_callable
    return execute_callable(context=context, **execute_callable_kwargs)
           ^^^^^^^^^^^^^^^^^^^^^^^^^^^^^^^^^^^^^^^^^^^^^^^^^^^^^^^^^^^^
  File "/home/airflow/.local/lib/python3.12/site-packages/airflow/models/baseoperator.py", line 400, in wrapper
    return func(self, *args, **kwargs)
           ^^^^^^^^^^^^^^^^^^^^^^^^^^^
  File "/home/airflow/.local/lib/python3.12/site-packages/airflow/operators/python.py", line 235, in execute
    return_value = self.execute_callable()
                   ^^^^^^^^^^^^^^^^^^^^^^^
  File "/home/airflow/.local/lib/python3.12/site-packages/airflow/operators/python.py", line 252, in execute_callable
    return self.python_callable(*self.op_args, **self.op_kwargs)
           ^^^^^^^^^^^^^^^^^^^^^^^^^^^^^^^^^^^^^^^^^^^^^^^^^^^^^
  File "/opt/airflow/dags/dag_equipment_sensors.py", line 29, in load_to_mysql
    return df.to_sql(table_name=, con=engine, if_exists='append', index=False)
                     ^^^^^^^^^^
NameError: name 'table_name' is not defined
[2024-04-15T00:11:58.093+0000] {taskinstance.py:1205} INFO - Marking task as FAILED. dag_id=extract_and_load_equipment_sensors, task_id=load_to_mysql, execution_date=20230619T000000, start_date=20240415T001157, end_date=20240415T001158
[2024-04-15T00:11:58.132+0000] {standard_task_runner.py:110} ERROR - Failed to execute job 1458 for task load_to_mysql (name 'table_name' is not defined; 4935)
[2024-04-15T00:11:58.192+0000] {local_task_job_runner.py:240} INFO - Task exited with return code 1
[2024-04-15T00:11:58.217+0000] {taskinstance.py:3482} INFO - 0 downstream tasks scheduled from follow-on schedule check
[2024-04-15T00:11:58.222+0000] {local_task_job_runner.py:222} INFO - ::endgroup::
