[2024-04-15T00:08:57.198+0000] {task_context_logger.py:104} ERROR - Executor reports task instance <TaskInstance: extract_and_load_equipment_sensors.transform_data scheduled__2023-01-01T00:00:00+00:00 [queued]> finished (failed) although the task says it's queued. (Info: None) Was the task killed externally?
