[2024-04-15T00:08:57.165+0000] {task_context_logger.py:104} ERROR - Executor reports task instance <TaskInstance: extract_and_load_equipment_sensors.load_to_mysql scheduled__2022-12-23T00:00:00+00:00 [queued]> finished (failed) although the task says it's queued. (Info: None) Was the task killed externally?
